Workbook

Sheet Zusammenfassung
A1: Zusammenfassung
C2: Bargeld | F2: Summe Einnahmen brutto | I2: Summe Einnahmen netto
A4: Einnahmen Abendkasse Freitag | C4: =+Einzelaufstellung!D36 -> 6365 | F4: =+C4 -> 6365 | G4: Bar | I4: =+F4/1.07 -> 5948.5981
A5: Einnahmen VVK Blüte und Stil | C5: =+Einzelaufstellung!G21 -> 1690 | F5: =+C5 -> 1690 | G5: Bar | I5: =+F5/1.07 -> 1579.4393
A6: Einnahme VVK Donner | C6: =+Einzelaufstellung!J21 -> 0
A7: Einnahmen VVK M1 (Abschöpfung) | C7: =+Einzelaufstellung!M21 -> 0
A8: Einnahmen Abendkasse Samstag | C8: =+Einzelaufstellung!P36 -> 6616.5 | F8: =+C8 -> 6616.5 | G8: Bar | I8: =+F8/1.07 -> 6183.6449
A10: Summe Einnahmen | C10: =SUM(C4:C9) -> 14671.5 | F10: =+C10 -> 14671.5 | I10: =SUM(I4:I8) -> 13711.682
A12: abzgl. Barhelfer | C12: =-Einzelaufstellung!P30 -> 0
A13: Wechselgeld/Reserve | C13: =+Einzelaufstellung!V36 -> 650
A14: abzgl. Toilettenwagen | C14: =-Einzelaufstellung!P32 -> 0
A15: abzgl. Becher Spülen | C15: =-Einzelaufstellung!D31 -> 0
A17: Bargeldbestand | C17: =SUM(C10:C15) -> 15321.5
A19: Einnahmen VVK Ditix Freitag | C19: =+Einzelaufstellung!Q60 -> 8182 | F19: =+C19 -> 8182 | G19: Ditix | I19: =+F19/1.07 -> 7646.729
A20: Einnahmen VVK Gebühr Freitag | C20: =+Einzelaufstellung!U60 -> 1036.76 | F20: =+C20 -> 1036.76 | G20: VVK Gebühr | I20: =+F20/1.19 -> 871.22689
A21: Einnahmen VVK Ditix Samstag | C21: =+Einzelaufstellung!Q74 -> 8750 | F21: =+C21 -> 8750 | G21: Ditix | I21: =+F21/1.07 -> 8177.5701
A22: Einnahmen VVK Gebühr Samstag | C22: =+Einzelaufstellung!U74 -> 1102.78 | F22: =+C22 -> 1102.78 | G22: VVK Gebühr | I22: =+F22/1.19 -> 926.70588
A24: Summe Einnahmen Ditix | C24: =SUM(C19:C23) -> 19071.54
A26: Noch ausstehende Abrechnung
A27: Hardticket (lr. Scan) 456 Verkaufte Ticket | C27: =+(456-130)*13 -> 4238 | D27: (geschätzt) | F27: =+C27 -> 4238 | I27: =+F27/1.19 -> 3561.3445
A28: abzgl Blüste und Stiel 130 verkaufte Ticket
A29: zzgl. Sponsoreneinnahmen | F29: 0 | G29: Brutto | I29: =+F29/1.19 -> 0
A31: Einnahmen | F31: =SUM(F10:F30) -> 37981.04 | G31: Gesamteinnahme | I31: =SUM(I10:I29) -> 34895.259

Sheet Tabelle1
A1: 107.7 | C1: 2500
A2: Werbung | C2: 2000
A3: Band | C3: =6*350 -> 2100
A4: Technik | C4: 2300
A5: Manu+Dani | C5: 600
A6: Scurity | C6: 2000
A7: Wareneinkauf Bar | C7: 1000
A8: Bardamen | C8: 450
C10: =SUM(C1:C9) -> 12950

Sheet Einzelaufstellung
A1: Abrechnung Nachfasching 2025
C4: Abendkasse Freitag | F4: VVK Blüte&Stil | I4: VVK Donner | L4: VVK M1 erste Abschöpfung | O4: Abendkasse Samstag | U4: Wechselgeld Freitag | X4: Wechsegeld Samstag | AA4: Summe | AD4: Check
A5: Scheine/Münzen | C5: Anzahl | D5: Betrag | F5: Anzahl | G5: Betrag | I5: Anzahl | J5: Betrag | L5: Anzahl | M5: Betrag | O5: Anzahl | P5: Betrag | R5: Anzahl | S5: Betrag | U5: Anzahl | V5: Betrag | X5: Anzahl | Y5: Betrag | AA5: Anzahl | AB5: Betrag | AD5: Anzahl | AE5: Betrag
A7: 100 | C7: 9 | D7: =+C7*$A$7 -> 900 | F7: 5 | G7: =+F7*$A$7 -> 500 | J7: =+I7*$A$7 -> 0 | M7: =+L7*$A$7 -> 0 | O7: 8 | P7: =+O7*$A$7 -> 800 | S7: =+R7*$A$7 -> 0 | V7: =+U7*$A$7 -> 0 | Y7: =+X7*$A$7 -> 0 | AA7: =+X7+U7+I7+F7+C7+L7+R7+O7 -> 22 | AB7: =+AA7*$A$7 -> 2200 | AD7: 22 | AE7: =+AD7*$A$7 -> 2200
A8: 50 | C8: 59 | D8: =+C8*$A$8 -> 2950 | F8: 13 | G8: =+F8*$A$8 -> 650 | J8: =+I8*$A$8 -> 0 | M8: =+L8*$A$8 -> 0 | O8: 70 | P8: =+O8*$A$8 -> 3500 | S8: =+R8*$A$8 -> 0 | U8: 0 | V8: =+U8*$A$8 -> 0 | X8: 0 | Y8: =+X8*$A$8 -> 0 | AA8: =+X8+U8+I8+F8+C8+L8+R8+O8 -> 142 | AB8: =+AA8*$A$8 -> 7100 | AD8: =66+76 -> 142 | AE8: =+AD8*$A$8 -> 7100
A9: 20 | C9: 83 | D9: =+C9*$A$9 -> 1660 | F9: 20 | G9: =+F9*$A$9 -> 400 | J9: =+I9*$A$9 -> 0 | M9: =+L9*$A$9 -> 0 | O9: 96 | P9: =+O9*$A$9 -> 1920 | S9: =+R9*$A$9 -> 0 | U9: 0 | V9: =+U9*$A$9 -> 0 | X9: 20 | Y9: =+X9*$A$9 -> 400 | AA9: =+X9+U9+I9+F9+C9+L9+R9+O9 -> 219 | AB9: =+AA9*$A$9 -> 4380 | AD9: =94+85 -> 179 | AE9: =+AD9*$A$9 -> 3580
A10: 10 | C10: 110 | D10: =+C10*$A$10 -> 1100 | F10: 6 | G10: =+F10*$A$10 -> 60 | J10: =+I10*$A$10 -> 0 | M10: =+L10*$A$10 -> 0 | O10: 117 | P10: =+O10*$A$10 -> 1170 | S10: =+R10*$A$10 -> 0 | U10: 30 | V10: =+U10*$A$10 -> 300 | X10: 30 | Y10: =+X10*$A$10 -> 300 | AA10: =+X10+U10+I10+F10+C10+L10+R10+O10 -> 293 | AB10: =+AA10*$A$10 -> 2930 | AD10: =107+96 -> 203 | AE10: =+AD10*$A$10 -> 2030
A11: 5 | C11: 34 | D11: =+C11*$A$11 -> 170 | F11: 16 | G11: =+F11*$A$11 -> 80 | J11: =+I11*$A$11 -> 0 | M11: =+L11*$A$11 -> 0 | O11: 19 | P11: =+O11*$A$11 -> 95 | S11: =+R11*$A$11 -> 0 | U11: 20 | V11: =+U11*$A$11 -> 100 | X11: 30 | Y11: =+X11*$A$11 -> 150 | AA11: =+X11+U11+I11+F11+C11+L11+R11+O11 -> 119 | AB11: =+AA11*$A$11 -> 595 | AD11: 39 | AE11: =+AD11*$A$11 -> 195
A12: 2 | C12: 5 | D12: =+C12*$A$12 -> 10 | G12: =+F12*$A$12 -> 0 | J12: =+I12*$A$12 -> 0 | M12: =+L12*$A$12 -> 0 | O12: 5 | P12: =+O12*$A$12 -> 10 | S12: =+R12*$A$12 -> 0 | U12: 0 | V12: =+U12*$A$12 -> 0 | X12: 5 | Y12: =+X12*$A$12 -> 10 | AA12: =+X12+U12+I12+F12+C12+L12+R12+O12 -> 15 | AB12: =+AA12*$A$12 -> 30 | AD12: 5 | AE12: =+AD12*$A$12 -> 10
A13: 1 | C13: 225 | D13: =+C13*$A$13 -> 225 | G13: =+F13*$A$13 -> 0 | J13: =+I13*$A$13 -> 0 | M13: =+L13*$A$13 -> 0 | O13: 203 | P13: =+O13*$A$13 -> 203 | S13: =+R13*$A$13 -> 0 | U13: 250 | V13: =+U13*$A$13 -> 250 | X13: =9*25 -> 225 | Y13: =+X13*$A$13 -> 225 | AA13: =+X13+U13+I13+F13+C13+L13+R13+O13 -> 903 | AB13: =+AA13*$A$13 -> 903 | AD13: =8*25+3 -> 203 | AE13: =+AD13*$A$13 -> 203
A14: 0.5 | D14: =+C14*$A$14 -> 0 | G14: =+F14*$A$14 -> 0 | J14: =+I14*$A$14 -> 0 | M14: =+L14*$A$14 -> 0 | O14: 5 | P14: =+O14*$A$14 -> 2.5 | S14: =+R14*$A$14 -> 0 | V14: =+U14*$A$14 -> 0 | Y14: =+X14*$A$14 -> 0 | AA14: =+X14+U14+I14+F14+C14+L14+R14+O14 -> 5 | AB14: =+AA14*$A$14 -> 2.5 | AD14: 5 | AE14: =+AD14*$A$14 -> 2.5
A15: 0.2 | D15: =+C15*$A$15 -> 0 | G15: =+F15*$A$15 -> 0 | J15: =+I15*$A$15 -> 0 | M15: =+L15*$A$15 -> 0 | O15: 5 | P15: =+O15*$A$15 -> 1 | S15: =+R15*$A$15 -> 0 | V15: =+U15*$A$15 -> 0 | Y15: =+X15*$A$15 -> 0 | AA15: =+X15+U15+I15+F15+C15+L15+R15+O15 -> 5 | AB15: =+AA15*$A$15 -> 1 | AD15: 5 | AE15: =+AD15*$A$15 -> 1
A16: 0.1 | D16: =+C16*$A$16 -> 0 | G16: =+F16*$A$16 -> 0 | J16: =+I16*$A$16 -> 0 | M16: =+L16*$A$16 -> 0 | P16: =+O16*$A$16 -> 0 | S16: =+R16*$A$16 -> 0 | V16: =+U16*$A$16 -> 0 | Y16: =+X16*$A$16 -> 0 | AA16: =+X16+U16+I16+F16+C16+L16+R16+O16 -> 0 | AB16: =+AA16*$A$16 -> 0 | AD16: 0 | AE16: =+AD16*$A$16 -> 0
A17: 0.05 | D17: =+C17*$A$17 -> 0 | G17: =+F17*$A$17 -> 0 | J17: =+I17*$A$17 -> 0 | M17: =+L17*$A$17 -> 0 | P17: =+O17*$A$17 -> 0 | S17: =+R17*$A$17 -> 0 | V17: =+U17*$A$17 -> 0 | Y17: =+X17*$A$17 -> 0 | AA17: =+X17+U17+I17+F17+C17+L17+R17+O17 -> 0 | AB17: =+AA17*$A$17 -> 0 | AD17: 0 | AE17: =+AD17*$A$17 -> 0
A18: 0.02 | D18: =+C18*$A$18 -> 0 | G18: =+F18*$A$18 -> 0 | J18: =+I18*$A$18 -> 0 | M18: =+L18*$A$18 -> 0 | P18: =+O18*$A$18 -> 0 | S18: =+R18*$A$18 -> 0 | V18: =+U18*$A$18 -> 0 | Y18: =+X18*$A$18 -> 0 | AA18: =+X18+U18+I18+F18+C18+L18+R18+O18 -> 0 | AB18: =+AA18*$A$18 -> 0 | AD18: 0 | AE18: =+AD18*$A$18 -> 0
A19: 0.01 | D19: =+C19*$A$19 -> 0 | G19: =+F19*$A$19 -> 0 | J19: =+I19*$A$19 -> 0 | M19: =+L19*$A$19 -> 0 | P19: =+O19*$A$19 -> 0 | S19: =+R19*$A$19 -> 0 | V19: =+U19*$A$19 -> 0 | Y19: =+X19*$A$19 -> 0 | AA19: =+X19+U19+I19+F19+C19+L19+R19+O19 -> 0 | AB19: =+AA19*$A$19 -> 0 | AD19: 0 | AE19: =+AD19*$A$19 -> 0
A21: Summe | D21: =SUM(D7:D19) -> 7015 | G21: =SUM(G7:G19) -> 1690 | J21: =SUM(J7:J19) -> 0 | M21: =SUM(M7:M19) -> 0 | P21: =SUM(P7:P19) -> 7701.5 | S21: =SUM(S7:S19) -> 0 | V21: =SUM(V7:V19) -> 650 | Y21: =SUM(Y7:Y19) -> 1085 | AB21: =SUM(AB7:AB19) -> 18141.5 | AE21: =SUM(AE7:AE19) -> 15321.5
A24: abzgl. Wechselgeld | D24: -650 | P24: =-Y21 -> -1085 | Y24: -1085 | AB24: =SUM(D24:AA24) -> -2820
A27: Bargeldbestand | D27: =+D21+D24 -> 6365 | G27: =+G21+G24 -> 1690 | J27: =+J21+J24 -> 0 | M27: =+M21+M24 -> 0 | P27: =+P21+P24 -> 6616.5 | S27: =+S21+S24 -> 0 | V27: =+V21+V24 -> 650 | Y27: =+Y21+Y24 -> 0 | AB27: =+AB21+AB24 -> 15321.5 | AE27: =+AE21-AB27 -> 0
AB30: =SUM(D30:AA30) -> 0
AB31: =SUM(D31:AA31) -> 0
AB32: =SUM(D32:AA32) -> 0
AB33: =SUM(D33:AA33) -> 0
A36: tatsächliche Einnahmen | D36: =SUM(D27:D35) -> 6365 | G36: =SUM(G27:G35) -> 1690 | J36: =SUM(J27:J35) -> 0 | M36: =SUM(M27:M35) -> 0 | P36: =SUM(P27:P35) -> 6616.5 | S36: =SUM(S27:S35) -> 0 | V36: =SUM(V27:V35) -> 650 | Y36: =SUM(Y27:Y35) -> 0 | AB36: =SUM(AB27:AB35) -> 15321.5
A39: Abendkasse | B39: 15 | C39: 415 | D39: =+B39*C39 -> 6225 | F39: 0 | G39: =+B39*F39 -> 0 | I39: 0 | J39: =+I39*B39 -> 0 | L39: 0 | M39: =+L39*B39 -> 0 | N39: 15 | O39: 424 | P39: =+O39*N39 -> 6360
A40: Abendkasse Kind | B40: 9 | C40: 10 | D40: =+B40*C40 -> 90 | F40: 0 | G40: =+B40*F40 -> 0 | I40: 0 | J40: =+I40*B40 -> 0 | L40: 0 | M40: =+L40*B40 -> 0 | N40: 9 | O40: 24 | P40: =+O40*N40 -> 216
A41: Abendkasse | B41: 10 | C41: 5 | D41: =+B41*C41 -> 50 | F41: 0 | G41: =+B41*F41 -> 0 | I41: 109 | J41: =+I41*B41 -> 1090 | L41: 100 | M41: =+L41*B41 -> 1000 | N41: 10 | O41: 4 | P41: =+O41*N41 -> 40
A42: VVK | B42: 13 | C42: 0 | D42: =+B42*C42 -> 0 | F42: 130 | G42: =+B42*F42 -> 1690 | I42: 0 | J42: =+I42*B42 -> 0 | L42: 0 | M42: =+L42*B42 -> 0 | O42: 0 | P42: =+O42*N42 -> 0
A44: Besucher Bargeld | C44: =SUM(C39:C43) -> 430 | D44: =SUM(D39:D43) -> 6365 | F44: =SUM(F39:F43) -> 130 | G44: =SUM(G39:G43) -> 1690 | I44: =SUM(I39:I43) -> 109 | J44: =SUM(J39:J43) -> 1090 | M44: =SUM(M39:M43) -> 1000 | N44: Besucher Bargeld | O44: =SUM(O39:O43) -> 452 | P44: =SUM(P39:P43) -> 6616
A45: (Abendkasse) | N45: (Abendkasse)
A47: Besucher Bargeld
A48: (Abendkasse) | C48: =+C44 -> 430 | N48: Freitag
A50: Ditix Besucher Freitag | N50: Karten lt. Ditiix | P50: Betrag errechnet | Q50: Betrag lt. Ditix | U50: Einnahmen Gebühren | X50: Differezn
A51: Online gescannt
A52: Hardtickets | C52: 265 | N52: 265 | O52: 13 | P52: =+N52*O52 -> 3445
A53: Treueticket | C53: 97 | N53: 100 | O53: 12 | P53: =+N53*O53 -> 1200 | Q53: 1200 | X53: =+P53-Q53 -> 0
A54: VVK | C54: 490 | N54: 502 | O54: 13 | P54: =+N54*O54 -> 6526 | Q54: 6526 | X54: =+P54-Q54 -> 0
A55: Abendkasse-ticket | C55: 26 | N55: 26 | O55: 15 | P55: =+N55*O55 -> 390 | Q55: 390
A56: Reservistenclub | C56: 6 | N56: 6 | O56: 11 | P56: =+N56*O56 -> 66 | Q56: 66
A57: Gästeliste | C57: 10 | N57: 12 | O57: 0 | P57: =+N57*O57 -> 0
...
