Workbook

Sheet Übersicht
A1: Vorschuss-Check 2026 · Hofbräu-Regiment
A2: Führen die laufenden Monatsvorschüsse zu einem ausgeglichenen Saldo am Jahresende? · Stand 31.08.2026
B4: Theo Hönig | C4: Pascal Göpel
A5: Im Regiment seit | B5: ="01.01.2026" -> 01.01.2026 | C5: ="01.04.2026" -> 01.04.2026
A6: Monatsvorschuss | B6: =Annahmen!$B$10 -> 1800 | C6: =Annahmen!$B$16 -> 1700
A7: Auftritte 2026 (F+M) | B7: ='Theo Hönig'!$B$5 -> 35 | C7: ='Pascal Göpel'!$B$5 -> 35
A8: Gagen netto | B8: ='Theo Hönig'!$B$6 -> 15200 | C8: ='Pascal Göpel'!$B$6 -> 15200
A9: Rechnung brutto (Jahresende) | B9: ='Theo Hönig'!$B$8 -> 16264 | C9: ='Pascal Göpel'!$B$8 -> 15200
A10: Vorschüsse gesamt 2026 | B10: ='Theo Hönig'!$B$13 -> 21600 | C10: ='Pascal Göpel'!$B$14 -> 14600
A11: Saldo (+ = Nachzahlung / – = zu viel gezahlt) | B11: ='Theo Hönig'!$B$16 -> -5336 | C11: ='Pascal Göpel'!$B$17 -> 600
A12: rechnerisch richtiger Monatsvorschuss | B12: ='Theo Hönig'!$B$18 -> 1355.3333 | C12: ='Pascal Göpel'!$B$19 -> 1775
A13: Zahl der Monatsvorschüsse | B13: =Annahmen!$B$11 -> 12 | C13: =Annahmen!$B$17 -> 8
A15: Was heißt das?
A16: • Beide kommen 2026 auf exakt 35 Auftritte und damit auf dieselbe Gagensumme von 15.200 € netto –
A17: Theo durch die drei Termine im Februar/März, Pascal durch Walker-Geburtstag und Rothaus Streetfood.
A18: • Pascal liegt mit 1.700 €/Monat nahezu punktgenau (600 € Nachzahlung am Jahresende) – keine Anpassung nötig.
A19: • Theo ist überzahlt, weil er 12 Monatsvorschüsse à 1.800 € erhält (21.600 €), Pascal dagegen nur 8 à 1.700 €
A20: plus 1.000 € Einmalzahlung (14.600 €). Rechnerisch richtig wären bei Theo rund 1.355 €/Monat.
A21: • Details und Stellschrauben je Person auf den Blättern „Theo Hönig“ und „Pascal Göpel“ (Abschnitt 4).
A22: • Mündlich zugesagte Termine sind wie fixe behandelt (Vorgabe Dirk) – das übliche Ausfallrisiko besteht bei
A23: fixen Zusagen gleichermaßen und wird hier nicht gesondert bewertet.

Sheet Annahmen
A1: Annahmen & Konditionen
A2: Hofbräu-Regiment · Gagen-/Vorschuss-Abgleich 2026 · Stand 31.08.2026
A4: Gagen
A5: Gage pro Auftritt (Normalsatz) | B5: 500 | C5: Angabe Dirk
A6: Gage pro Auftritt (reduzierter Satz) | B6: 350 | C6: Angabe Dirk – gilt für Wintermarkt Rothaus, Stuttgarter Frühlingsfest und Cannstatter Volksfest
A7: Gage Benefizkonzert | B7: 0 | C7: 13.12.2026 Benefiz Ludwigsburg – keine Gage
A9: Theo Hönig
A10: Vorschuss pro Monat | B10: 1800 | C10: seit 01.01.2026
A11: Anzahl Monate 2026 | B11: 12 | C11: Jan–Dez 2026
A12: MwSt-Satz | B12: 0.07 | C12: Theo stellt Jahresrechnung mit 7 % MwSt
A13: Vorschuss ist … (1 = brutto inkl. MwSt) | B13: 1 | C13: Vorgabe Dirk: Vorschüsse sind brutto zu verstehen
A15: Pascal Göpel
A16: Vorschuss pro Monat | B16: 1700 | C16: seit 01.05.2026
A17: Anzahl Monate 2026 | B17: 8 | C17: Mai–Dez 2026
A18: Einmalzahlung 25.04.2026 | B18: 1000 | C18: Angabe Dirk
A19: MwSt-Satz | B19: 0 | C19: Pascal ist von der Mehrwertsteuer befreit
A21: Wer spielt welche Auftritte?
A22: • Pascal Göpel: Sänger seit 01.04.2026 → alle Auftritte ab dem 01.04.2026.
A23: • Theo Hönig: spielt seit Jahresanfang – NICHT dabei: Wintermarkt Rothaus (31.01.–04.02.), Geburtstag Walker (22.08.), Rothaus Streetfood (12.+13.09.).
A24: • Berücksichtigt werden Termine mit Status Fix (F) und Mündlich (M). Status Angefragt (A) bleibt außen vor (Vorgabe Dirk).
A25: • Benefizkonzert 13.12.2026 Ludwigsburg: keine Gage für beide.
A26: • Datenquelle Termine: CRM-Kalender (Supabase), Band-ID 22 = Hofbräu-Regiment, abgerufen 31.08.2026.
A28: Offener Punkt / Annahme
A29: Bei Theo ist unterstellt: die Gage (500 € / 350 €) ist ein NETTO-Betrag, die 7 % MwSt kommen
A30: auf der Jahresrechnung obendrauf. Alternativszenario (Gage = brutto inkl. 7 %) siehe Blatt „Theo Hönig“.

Sheet Auftritte 2026
A1: Auftritte Hofbräu-Regiment 2026
A2: Quelle: CRM-Kalender (Band-ID 22), Stand 31.08.2026 · Status: F = Fix, M = Mündlich, A = Angefragt (nicht gewertet)
A4: Datum | B4: Veranstaltung | C4: Veranstalter / Ort | D4: Status | E4: Gagen-Typ | F4: Gage/Auftritt | G4: Theo dabei | H4: Pascal dabei | I4: Gage Theo | J4: Gage Pascal | K4: Bemerkung
A5: 46053 | B5: Wintermarkt Rothaus | C5: Badische Staatsbrauerei Rothaus | D5: F | E5: reduziert | F5: =IF($D5="A",0,IF($E5="Benefiz",Annahmen!$B$7,IF($E5="reduziert",Annahmen!$B$6,Annahmen!$B$5))) -> 350 | G5: 0 | H5: 0 | I5: =$F5*$G5 -> 0 | J5: =$F5*$H5 -> 0 | K5: Theo nicht dabei / vor Pascals Zeit
A6: 46054 | B6: Wintermarkt Rothaus | C6: Badische Staatsbrauerei Rothaus | D6: F | E6: reduziert | F6: =IF($D6="A",0,IF($E6="Benefiz",Annahmen!$B$7,IF($E6="reduziert",Annahmen!$B$6,Annahmen!$B$5))) -> 350 | G6: 0 | H6: 0 | I6: =$F6*$G6 -> 0 | J6: =$F6*$H6 -> 0 | K6: Theo nicht dabei / vor Pascals Zeit
A7: 46055 | B7: Wintermarkt Rothaus | C7: Badische Staatsbrauerei Rothaus | D7: F | E7: reduziert | F7: =IF($D7="A",0,IF($E7="Benefiz",Annahmen!$B$7,IF($E7="reduziert",Annahmen!$B$6,Annahmen!$B$5))) -> 350 | G7: 0 | H7: 0 | I7: =$F7*$G7 -> 0 | J7: =$F7*$H7 -> 0 | K7: Theo nicht dabei / vor Pascals Zeit
A8: 46056 | B8: Wintermarkt Rothaus | C8: Badische Staatsbrauerei Rothaus | D8: F | E8: reduziert | F8: =IF($D8="A",0,IF($E8="Benefiz",Annahmen!$B$7,IF($E8="reduziert",Annahmen!$B$6,Annahmen!$B$5))) -> 350 | G8: 0 | H8: 0 | I8: =$F8*$G8 -> 0 | J8: =$F8*$H8 -> 0 | K8: Theo nicht dabei / vor Pascals Zeit
A9: 46057 | B9: Wintermarkt Rothaus | C9: Badische Staatsbrauerei Rothaus | D9: F | E9: reduziert | F9: =IF($D9="A",0,IF($E9="Benefiz",Annahmen!$B$7,IF($E9="reduziert",Annahmen!$B$6,Annahmen!$B$5))) -> 350 | G9: 0 | H9: 0 | I9: =$F9*$G9 -> 0 | J9: =$F9*$H9 -> 0 | K9: Theo nicht dabei / vor Pascals Zeit
A10: 46065 | B10: Rielasingen | D10: F | E10: Normal | F10: =IF($D10="A",0,IF($E10="Benefiz",Annahmen!$B$7,IF($E10="reduziert",Annahmen!$B$6,Annahmen!$B$5))) -> 500 | G10: 1 | H10: 0 | I10: =$F10*$G10 -> 500 | J10: =$F10*$H10 -> 0 | K10: vor Pascals Zeit
A11: 46066 | B11: Fasching Münchingen | D11: F | E11: Normal | F11: =IF($D11="A",0,IF($E11="Benefiz",Annahmen!$B$7,IF($E11="reduziert",Annahmen!$B$6,Annahmen!$B$5))) -> 500 | G11: 1 | H11: 0 | I11: =$F11*$G11 -> 500 | J11: =$F11*$H11 -> 0 | K11: vor Pascals Zeit
A12: 46087 | B12: Hausärztetag | C12: Stuttgart | D12: F | E12: Normal | F12: =IF($D12="A",0,IF($E12="Benefiz",Annahmen!$B$7,IF($E12="reduziert",Annahmen!$B$6,Annahmen!$B$5))) -> 500 | G12: 1 | H12: 0 | I12: =$F12*$G12 -> 500 | J12: =$F12*$H12 -> 0 | K12: vor Pascals Zeit
A13: 46123 | B13: Wasenopening 2026 | C13: Marco Di Pilla | D13: F | E13: Normal | F13: =IF($D13="A",0,IF($E13="Benefiz",Annahmen!$B$7,IF($E13="reduziert",Annahmen!$B$6,Annahmen!$B$5))) -> 500 | G13: 1 | H13: 1 | I13: =$F13*$G13 -> 500 | J13: =$F13*$H13 -> 500 | K13: Normalsatz
A14: 46130 | B14: Stuttgarter Frühlingsfest | C14: Beim Benz | D14: M | E14: reduziert | F14: =IF($D14="A",0,IF($E14="Benefiz",Annahmen!$B$7,IF($E14="reduziert",Annahmen!$B$6,Annahmen!$B$5))) -> 350 | G14: 1 | H14: 1 | I14: =$F14*$G14 -> 350 | J14: =$F14*$H14 -> 350
A15: 46131 | B15: Stuttgarter Frühlingsfest | C15: Beim Benz | D15: M | E15: reduziert | F15: =IF($D15="A",0,IF($E15="Benefiz",Annahmen!$B$7,IF($E15="reduziert",Annahmen!$B$6,Annahmen!$B$5))) -> 350 | G15: 1 | H15: 1 | I15: =$F15*$G15 -> 350 | J15: =$F15*$H15 -> 350
A16: 46135 | B16: Stuttgarter Frühlingsfest | C16: Beim Benz | D16: M | E16: reduziert | F16: =IF($D16="A",0,IF($E16="Benefiz",Annahmen!$B$7,IF($E16="reduziert",Annahmen!$B$6,Annahmen!$B$5))) -> 350 | G16: 1 | H16: 1 | I16: =$F16*$G16 -> 350 | J16: =$F16*$H16 -> 350
A17: 46136 | B17: Stuttgarter Frühlingsfest | C17: Beim Benz | D17: M | E17: reduziert | F17: =IF($D17="A",0,IF($E17="Benefiz",Annahmen!$B$7,IF($E17="reduziert",Annahmen!$B$6,Annahmen!$B$5))) -> 350 | G17: 1 | H17: 1 | I17: =$F17*$G17 -> 350 | J17: =$F17*$H17 -> 350
A18: 46142 | B18: Maifest Bettringen | D18: F | E18: Normal | F18: =IF($D18="A",0,IF($E18="Benefiz",Annahmen!$B$7,IF($E18="reduziert",Annahmen!$B$6,Annahmen!$B$5))) -> 500 | G18: 1 | H18: 1 | I18: =$F18*$G18 -> 500 | J18: =$F18*$H18 -> 500
A19: 46147 | B19: Stuttgarter Frühlingsfest | C19: Beim Benz | D19: M | E19: reduziert | F19: =IF($D19="A",0,IF($E19="Benefiz",Annahmen!$B$7,IF($E19="reduziert",Annahmen!$B$6,Annahmen!$B$5))) -> 350 | G19: 1 | H19: 1 | I19: =$F19*$G19 -> 350 | J19: =$F19*$H19 -> 350
A20: 46148 | B20: Stuttgarter Frühlingsfest | C20: Beim Benz | D20: M | E20: reduziert | F20: =IF($D20="A",0,IF($E20="Benefiz",Annahmen!$B$7,IF($E20="reduziert",Annahmen!$B$6,Annahmen!$B$5))) -> 350 | G20: 1 | H20: 1 | I20: =$F20*$G20 -> 350 | J20: =$F20*$H20 -> 350
A21: 46151 | B21: Stuttgarter Frühlingsfest | C21: Beim Benz | D21: M | E21: reduziert | F21: =IF($D21="A",0,IF($E21="Benefiz",Annahmen!$B$7,IF($E21="reduziert",Annahmen!$B$6,Annahmen!$B$5))) -> 350 | G21: 1 | H21: 1 | I21: =$F21*$G21 -> 350 | J21: =$F21*$H21 -> 350
A22: 46152 | B22: Stuttgarter Frühlingsfest | C22: Beim Benz | D22: M | E22: reduziert | F22: =IF($D22="A",0,IF($E22="Benefiz",Annahmen!$B$7,IF($E22="reduziert",Annahmen!$B$6,Annahmen!$B$5))) -> 350 | G22: 1 | H22: 1 | I22: =$F22*$G22 -> 350 | J22: =$F22*$H22 -> 350
A23: 46155 | B23: Berglesbond 2026 | D23: F | E23: Normal | F23: =IF($D23="A",0,IF($E23="Benefiz",Annahmen!$B$7,IF($E23="reduziert",Annahmen!$B$6,Annahmen!$B$5))) -> 500 | G23: 1 | H23: 1 | I23: =$F23*$G23 -> 500 | J23: =$F23*$H23 -> 500
A24: 46185 | B24: Stadtfest Schwäbisch Gmünd | D24: F | E24: Normal | F24: =IF($D24="A",0,IF($E24="Benefiz",Annahmen!$B$7,IF($E24="reduziert",Annahmen!$B$6,Annahmen!$B$5))) -> 500 | G24: 1 | H24: 1 | I24: =$F24*$G24 -> 500 | J24: =$F24*$H24 -> 500
A25: 46206 | B25: Stadtkapelle Wernau | D25: F | E25: Normal | F25: =IF($D25="A",0,IF($E25="Benefiz",Annahmen!$B$7,IF($E25="reduziert",Annahmen!$B$6,Annahmen!$B$5))) -> 500 | G25: 1 | H25: 1 | I25: =$F25*$G25 -> 500 | J25: =$F25*$H25 -> 500
A26: 46213 | B26: HSN Denkendorf | D26: F | E26: Normal | F26: =IF($D26="A",0,IF($E26="Benefiz",Annahmen!$B$7,IF($E26="reduziert",Annahmen!$B$6,Annahmen!$B$5))) -> 500 | G26: 1 | H26: 1 | I26: =$F26*$G26 -> 500 | J26: =$F26*$H26 -> 500
A27: 46214 | B27: Motocross Aichwald | D27: F | E27: Normal | F27: =IF($D27="A",0,IF($E27="Benefiz",Annahmen!$B$7,IF($E27="reduziert",Annahmen!$B$6,Annahmen!$B$5))) -> 500 | G27: 1 | H27: 1 | I27: =$F27*$G27 -> 500 | J27: =$F27*$H27 -> 500
A28: 46221 | B28: SC Freiburg Fanfest | C28: Rothaus AG, Grafenhausen | D28: F | E28: Normal | F28: =IF($D28="A",0,IF($E28="Benefiz",Annahmen!$B$7,IF($E28="reduziert",Annahmen!$B$6,Annahmen!$B$5))) -> 500 | G28: 1 | H28: 1 | I28: =$F28*$G28 -> 500 | J28: =$F28*$H28 -> 500
A29: 46225 | B29: VR-Bank Sommerfest | C29: VR-Bank | D29: F | E29: Normal | F29: =IF($D29="A",0,IF($E29="Benefiz",Annahmen!$B$7,IF($E29="reduziert",Annahmen!$B$6,Annahmen!$B$5))) -> 500 | G29: 1 | H29: 1 | I29: =$F29*$G29 -> 500 | J29: =$F29*$H29 -> 500
A30: 46235 | B30: Ochsenfest Stangenbach | C30: Stammtisch Stangenbach e.V. | D30: F | E30: Normal | F30: =IF($D30="A",0,IF($E30="Benefiz",Annahmen!$B$7,IF($E30="reduziert",Annahmen!$B$6,Annahmen!$B$5))) -> 500 | G30: 1 | H30: 1 | I30: =$F30*$G30 -> 500 | J30: =$F30*$H30 -> 500
A31: 46256 | B31: Open Air – Geburtstag Walker | C31: geschlossene Gesellschaft | D31: F | E31: Normal | F31: =IF($D31="A",0,IF($E31="Benefiz",Annahmen!$B$7,IF($E31="reduziert",Annahmen!$B$6,Annahmen!$B$5))) -> 500 | G31: 0 | H31: 1 | I31: =$F31*$G31 -> 0 | J31: =$F31*$H31 -> 500 | K31: Theo nicht dabei
A32: 46277 | B32: Rothaus Streetfood / Foodtruck | C32: Rothaus AG | D32: F | E32: Normal | F32: =IF($D32="A",0,IF($E32="Benefiz",Annahmen!$B$7,IF($E32="reduziert",Annahmen!$B$6,Annahmen!$B$5))) -> 500 | G32: 0 | H32: 1 | I32: =$F32*$G32 -> 0 | J32: =$F32*$H32 -> 500 | K32: Theo nicht dabei
A33: 46278 | B33: Rothaus Streetfood / Foodtruck | C33: Rothaus AG | D33: F | E33: Normal | F33: =IF($D33="A",0,IF($E33="Benefiz",Annahmen!$B$7,IF($E33="reduziert",Annahmen!$B$6,Annahmen!$B$5))) -> 500 | G33: 0 | H33: 1 | I33: =$F33*$G33 -> 0 | J33: =$F33*$H33 -> 500 | K33: Theo nicht dabei
A34: 46283 | B34: Oktoberfest Koblenz | D34: F | E34: Normal | F34: =IF($D34="A",0,IF($E34="Benefiz",Annahmen!$B$7,IF($E34="reduziert",Annahmen!$B$6,Annahmen!$B$5))) -> 500 | G34: 1 | H34: 1 | I34: =$F34*$G34 -> 500 | J34: =$F34*$H34 -> 500
A35: 46284 | B35: Oktoberfest Koblenz | D35: F | E35: Normal | F35: =IF($D35="A",0,IF($E35="Benefiz",Annahmen!$B$7,IF($E35="reduziert",Annahmen!$B$6,Annahmen!$B$5))) -> 500 | G35: 1 | H35: 1 | I35: =$F35*$G35 -> 500 | J35: =$F35*$H35 -> 500
A36: 46289 | B36: Erbenheim | D36: M | E36: Normal | F36: =IF($D36="A",0,IF($E36="Benefiz",Annahmen!$B$7,IF($E36="reduziert",Annahmen!$B$6,Annahmen!$B$5))) -> 500 | G36: 1 | H36: 1 | I36: =$F36*$G36 -> 500 | J36: =$F36*$H36 -> 500
A37: 46291 | B37: Cannstatter Volksfest | C37: Beim Benz im Hofbräuzelt | D37: M | E37: reduziert | F37: =IF($D37="A",0,IF($E37="Benefiz",Annahmen!$B$7,IF($E37="reduziert",Annahmen!$B$6,Annahmen!$B$5))) -> 350 | G37: 1 | H37: 1 | I37: =$F37*$G37 -> 350 | J37: =$F37*$H37 -> 350
A38: 46292 | B38: Cannstatter Volksfest | C38: Beim Benz im Hofbräuzelt | D38: M | E38: reduziert | F38: =IF($D38="A",0,IF($E38="Benefiz",Annahmen!$B$7,IF($E38="reduziert",Annahmen!$B$6,Annahmen!$B$5))) -> 350 | G38: 1 | H38: 1 | I38: =$F38*$G38 -> 350 | J38: =$F38*$H38 -> 350
A39: 46296 | B39: Cannstatter Volksfest | C39: Beim Benz im Hofbräuzelt | D39: M | E39: reduziert | F39: =IF($D39="A",0,IF($E39="Benefiz",Annahmen!$B$7,IF($E39="reduziert",Annahmen!$B$6,Annahmen!$B$5))) -> 350 | G39: 1 | H39: 1 | I39: =$F39*$G39 -> 350 | J39: =$F39*$H39 -> 350
A40: 46297 | B40: BOF – Rothaus Treffpunkt Zelt | D40: M | E40: Normal | F40: =IF($D40="A",0,IF($E40="Benefiz",Annahmen!$B$7,IF($E40="reduziert",Annahmen!$B$6,Annahmen!$B$5))) -> 500 | G40: 1 | H40: 1 | I40: =$F40*$G40 -> 500 | J40: =$F40*$H40 -> 500
A41: 46298 | B41: BOF – Rothaus Treffpunkt Zelt | D41: M | E41: Normal | F41: =IF($D41="A",0,IF($E41="Benefiz",Annahmen!$B$7,IF($E41="reduziert",Annahmen!$B$6,Annahmen!$B$5))) -> 500 | G41: 1 | H41: 1 | I41: =$F41*$G41 -> 500 | J41: =$F41*$H41 -> 500
...

Sheet Pascal Göpel
A1: Pascal Göpel
A2: Sänger Hofbräu-Regiment seit 01.04.2026 · Vorschuss 1.700 €/Monat seit 01.05.2026 · von der MwSt befreit
A4: 1 · Gagen 2026 (F + M)
A5: Anzahl Auftritte | B5: ='Auftritte 2026'!$H$49 -> 35
A6: Gagen gesamt (netto) | B6: ='Auftritte 2026'!$J$49 -> 15200
A7: zzgl. MwSt | B7: 0
A8: Rechnungsbetrag Jahresende (brutto) | B8: =$B$6+$B$7 -> 15200
A10: 2 · Vorschüsse 2026
A11: Vorschuss pro Monat | B11: =Annahmen!$B$16 -> 1700
A12: Anzahl Monate | B12: =Annahmen!$B$17 -> 8
A13: Einmalzahlung 25.04.2026 | B13: =Annahmen!$B$18 -> 1000
A14: Vorschüsse gesamt 2026 | B14: =$B$11*$B$12+$B$13 -> 14600
A16: 3 · Saldo zum Jahresende
A17: Saldo (Rechnung ./. Vorschüsse) | B17: =$B$8-$B$14 -> 600
A18: Lesart | B18: =IF($B$17>0,"Nachzahlung an "&"Pascal",IF($B$17<0,"Überzahlung – Rückforderung / Verrechnung","ausgeglichen")) -> Nachzahlung an Pascal
A19: rechnerisch richtiger Monatsvorschuss | B19: =($B$8-Annahmen!$B$18)/Annahmen!$B$17 -> 1775
A20: Differenz zum tatsächlichen Vorschuss | B20: =$B$19-$B$11 -> 75
A22: 4 · Steuerung ab Oktober 2026
A23: bereits gezahlt (Einmalzahlung + Mai–Sep, 5 Monate) | B23: =Annahmen!$B$18+Annahmen!$B$16*5 -> 9500
A24: verbleibende Monatszahlungen (Okt–Dez) | B24: 3
A25: offener Restbetrag bis Jahresende | B25: =$B$8-$B$23 -> 5700
A26: → Vorschuss Okt–Dez für exakten Ausgleich | B26: =IF($B$24=0,0,$B$25/$B$24) -> 1900
A27: Differenz zum aktuellen Vorschuss | B27: =$B$26-$B$11 -> 200

Sheet Theo Hönig
A1: Theo Hönig
A2: Vorschuss 1.800 €/Monat seit 01.01.2026 · Jahresrechnung mit 7 % MwSt
A4: 1 · Gagen 2026 (F + M)
A5: Anzahl Auftritte | B5: ='Auftritte 2026'!$G$49 -> 35
A6: Gagen gesamt (netto) | B6: ='Auftritte 2026'!$I$49 -> 15200
A7: zzgl. MwSt | B7: =$B$6*Annahmen!$B$12 -> 1064
A8: Rechnungsbetrag Jahresende (brutto) | B8: =$B$6+$B$7 -> 16264
A10: 2 · Vorschüsse 2026
A11: Vorschuss pro Monat | B11: =Annahmen!$B$10 -> 1800
A12: Anzahl Monate | B12: =Annahmen!$B$11 -> 12
A13: Vorschüsse gesamt 2026 | B13: =$B$11*$B$12 -> 21600
A15: 3 · Saldo zum Jahresende
A16: Saldo (Rechnung ./. Vorschüsse) | B16: =$B$8-$B$13 -> -5336
A17: Lesart | B17: =IF($B$16>0,"Nachzahlung an "&"Theo",IF($B$16<0,"Überzahlung – Rückforderung / Verrechnung","ausgeglichen")) -> Überzahlung – Rückforderung / Verrechnung
A18: rechnerisch richtiger Monatsvorschuss | B18: =($B$8)/Annahmen!$B$11 -> 1355.3333
A19: Differenz zum tatsächlichen Vorschuss | B19: =$B$18-$B$11 -> -444.66667
A21: 4 · Steuerung ab Oktober 2026
A22: bereits gezahlt (Jan–Sep, 9 Monate – Septemberrate ist bereits ausbezahlt) | B22: =Annahmen!$B$10*9 -> 16200
A23: verbleibende Monatszahlungen (Okt–Dez) | B23: 3
A24: offener Restbetrag bis Jahresende | B24: =$B$8-$B$22 -> 64
A25: → Vorschuss Okt–Dez für exakten Ausgleich | B25: =IF($B$23=0,0,$B$24/$B$23) -> 21.333333
A26: Differenz zum aktuellen Vorschuss | B26: =$B$25-$B$11 -> -1778.6667
A28: 6 · Alternative: Gage 500 €/350 € ist bereits brutto (inkl. 7 %)
A29: Rechnungsbetrag brutto = Gagensumme | B29: =$B$6 -> 15200
A30: davon MwSt 7 % | B30: =$B$29-$B$29/(1+Annahmen!$B$12) -> 994.39252
A31: Saldo in diesem Fall | B31: =$B$29-$B$13 -> -6400
A32: Bitte klären: In der Hauptrechnung oben ist Variante „netto + 7 %“ unterstellt.
